<?xml version="1.0" ?>
<!-- =================================================================================== -->
<!-- |    This document was autogenerated by xacro from /home/nguyenan/ros2_ws/src/elder_robot/urdf/elderbot.urdf.xacro | -->
<!-- |    EDITING THIS FILE BY HAND IS NOT RECOMMENDED                                 | -->
<!-- =================================================================================== -->
<robot name="elderbot">
  <!-- Laser (LiDAR) -->
  <joint name="laser_joint" type="fixed">
    <parent link="chassis"/>
    <child link="laser_frame"/>
    <origin rpy="0 0 0" xyz="-0.04625 0 0.135"/>
  </joint>
  <link name="laser_frame">
    <visual>
      <geometry>
        <cylinder length="0.03" radius="0.03"/>
      </geometry>
      <material name="black">
        <color rgba="0 0 0 1.0"/>
      </material>
    </visual>
    <collision>
      <geometry>
        <cylinder length="0.03" radius="0.03"/>
      </geometry>
    </collision>
    <inertial>
      <mass value="0.1"/>
      <inertia ixx="7.583333333333335e-05" ixy="0" ixz="0" iyy="0.00012500000000000003" iyz="0" izz="7.583333333333335e-05"/>
    </inertial>
  </link>
  <gazebo reference="laser_frame">
    <material>Gazebo/Black</material>
  </gazebo>
  <gazebo reference="laser_frame">
    <sensor name="lidar" type="ray">
      <pose>0 0 0 0 0 0</pose>
      <visualize>true</visualize>
      <update_rate>10</update_rate>
      <ray>
        <scan>
          <horizontal>
            <samples>359</samples>
            <min_angle>-3.14</min_angle>
            <max_angle>3.122</max_angle>
          </horizontal>
        </scan>
        <range>
          <min>0.3</min>
          <max>12</max>
          <resolution>0.01</resolution>
        </range>
      </ray>
      <plugin filename="libgazebo_ros_ray_sensor.so" name="gazebo_ros_ray_sensor">
        <ros>
          <argument>~/out:=scan</argument>
          <parameter name="frame_name" value="laser_frame"/>
        </ros>
        <output_type>sensor_msgs/LaserScan</output_type>
        <frameName>laser_frame</frameName>
      </plugin>
    </sensor>
  </gazebo>
  <!--height_box = height_total(27) - wheel_radius - LiDAR-->
  <!-- Base link -->
  <link name="base_link">
    </link>
  <link name="base_footprint"/>
  <joint name="base_footprint_joint" type="fixed">
    <parent link="base_footprint"/>
    <child link="base_link"/>
    <origin rpy="0 0 0" xyz="0 0 0.152"/>
  </joint>
  <!-- CHASSIS -->
  <joint name="chassis_joint" type="fixed">
    <parent link="base_link"/>
    <child link="chassis"/>
    <origin xyz="0 0 0"/>
  </joint>
  <link name="chassis">
    <visual>
      <origin xyz="0 0 0"/>
      <geometry>
        <box size="0.185 0.166 0.24"/>
      </geometry>
    </visual>
    <collision>
      <origin xyz="0 0 0"/>
      <geometry>
        <box size="0.185 0.166 0.24"/>
      </geometry>
    </collision>
    <inertial>
      <mass value="2.15"/>
      <inertia ixx="0.015257116666666666" ixy="0" ixz="0" iyy="0.01645197916666666" iyz="0" izz="0.011069095833333332"/>
    </inertial>
  </link>
  <!-- WHEEL LINKS -->
  <!-- FRONT WHEELS -->
  <link name="left_front_wheel">
    <visual>
      <geometry>
        <cylinder length="0.025" radius="0.032"/>
      </geometry>
    </visual>
    <material name="blue">
      <color rgba="0 0 1 1.0"/>
    </material>
    <collision>
      <geometry>
        <cylinder length="0.025" radius="0.032"/>
      </geometry>
    </collision>
    <inertial>
      <mass value="0.035"/>
      <inertia ixx="1.0782916666666668e-05" ixy="0" ixz="0" iyy="1.792e-05" iyz="0" izz="1.0782916666666668e-05"/>
    </inertial>
  </link>
  <gazebo reference="left_front_wheel">
    <material>Gazebo/Blue</material>
  </gazebo>
  <link name="right_front_wheel">
    <visual>
      <geometry>
        <cylinder length="0.025" radius="0.032"/>
      </geometry>
    </visual>
    <material name="blue">
      <color rgba="0 0 1 1.0"/>
    </material>
    <collision>
      <geometry>
        <cylinder length="0.025" radius="0.032"/>
      </geometry>
    </collision>
    <inertial>
      <mass value="0.035"/>
      <inertia ixx="1.0782916666666668e-05" ixy="0" ixz="0" iyy="1.792e-05" iyz="0" izz="1.0782916666666668e-05"/>
    </inertial>
  </link>
  <gazebo reference="right_front_wheel">
    <material>Gazebo/Blue</material>
  </gazebo>
  <!-- REAR WHEELS -->
  <link name="left_rear_wheel">
    <visual>
      <geometry>
        <cylinder length="0.025" radius="0.032"/>
      </geometry>
    </visual>
    <material name="blue">
      <color rgba="0 0 1 1.0"/>
    </material>
    <collision>
      <geometry>
        <cylinder length="0.025" radius="0.032"/>
      </geometry>
    </collision>
    <inertial>
      <mass value="0.035"/>
      <inertia ixx="1.0782916666666668e-05" ixy="0" ixz="0" iyy="1.792e-05" iyz="0" izz="1.0782916666666668e-05"/>
    </inertial>
  </link>
  <gazebo reference="left_rear_wheel">
    <material>Gazebo/Blue</material>
  </gazebo>
  <link name="right_rear_wheel">
    <visual>
      <geometry>
        <cylinder length="0.025" radius="0.032"/>
      </geometry>
    </visual>
    <material name="blue">
      <color rgba="0 0 1 1.0"/>
    </material>
    <collision>
      <geometry>
        <cylinder length="0.025" radius="0.032"/>
      </geometry>
    </collision>
    <inertial>
      <mass value="0.035"/>
      <inertia ixx="1.0782916666666668e-05" ixy="0" ixz="0" iyy="1.792e-05" iyz="0" izz="1.0782916666666668e-05"/>
    </inertial>
  </link>
  <gazebo reference="right_rear_wheel">
    <material>Gazebo/Blue</material>
  </gazebo>
  <!-- WHEEL JOINTS -->
  <joint name="left_front_wheel_joint" type="continuous">
    <parent link="base_link"/>
    <child link="left_front_wheel"/>
    <origin rpy="-1.5707963267948966 0 0" xyz="0.0925 0.0955 -0.12"/>
    <axis xyz="0 0 1"/>
  </joint>
  <joint name="right_front_wheel_joint" type="continuous">
    <parent link="base_link"/>
    <child link="right_front_wheel"/>
    <origin rpy="1.5707963267948966 0 0" xyz="0.0925 -0.0955 -0.12"/>
    <axis xyz="0 0 -1"/>
  </joint>
  <joint name="left_rear_wheel_joint" type="continuous">
    <parent link="base_link"/>
    <child link="left_rear_wheel"/>
    <origin rpy="-1.5707963267948966 0 0" xyz="-0.0925 0.0955 -0.12"/>
    <axis xyz="0 0 1"/>
  </joint>
  <joint name="right_rear_wheel_joint" type="continuous">
    <parent link="base_link"/>
    <child link="right_rear_wheel"/>
    <origin rpy="1.5707963267948966 0 0" xyz="-0.0925 -0.0955 -0.12"/>
    <axis xyz="0 0 -1"/>
  </joint>
  <gazebo>
    <plugin filename="libgazebo_ros_diff_drive.so" name="diff_drive">
      <update_rate>10</update_rate>
      <left_joint>left_rear_wheel_joint</left_joint>
      <right_joint>right_rear_wheel_joint</right_joint>
      <wheel_separation>0.191</wheel_separation>
      <wheel_diameter>0.064</wheel_diameter>
      <max_wheel_torque>20</max_wheel_torque>
      <max_wheel_acceleration>1.0</max_wheel_acceleration>
      <odometry_frame>odom</odometry_frame>
      <robot_base_frame>base_footprint</robot_base_frame>
      <publish_odom>true</publish_odom>
      <publish_odom_tf>true</publish_odom_tf>
      <publish_wheel_tf>false</publish_wheel_tf>
      <ros>
        <namespace>/</namespace>
        <remapping>cmd_vel:=cmd_vel</remapping>
        <remapping>odom:=odom</remapping>
      </ros>
    </plugin>
    <plugin filename="libgazebo_ros_joint_state_publisher.so" name="joint_state_publisher">
      <update_rate>10</update_rate>
      <joint_name>left_front_wheel_joint</joint_name>
      <joint_name>right_front_wheel_joint</joint_name>
      <joint_name>left_rear_wheel_joint</joint_name>
      <joint_name>right_rear_wheel_joint</joint_name>
    </plugin>
  </gazebo>
</robot>
