<sdf version='1.6'>
  <world name='simple_world'>
    <model name='ground_plane'>
      <static>1</static>
      <link name='link'>
        <collision name='collision'>
          <geometry>
            <plane>
              <normal>0 0 1</normal>
              <size>100 100</size>
            </plane>
          </geometry>
          <surface>
            <friction>
              <ode>
                <mu>100</mu>
                <mu2>50</mu2>
              </ode>
              <torsional>
                <ode/>
              </torsional>
            </friction>
            <contact>
              <ode/>
            </contact>
            <bounce/>
          </surface>
          <max_contacts>10</max_contacts>
        </collision>
        <visual name='visual'>
          <cast_shadows>0</cast_shadows>
          <geometry>
            <plane>
              <normal>0 0 1</normal>
              <size>100 100</size>
            </plane>
          </geometry>
          <material>
            <script>
              <uri>file://media/materials/scripts/gazebo.material</uri>
              <name>Gazebo/Grey</name>
            </script>
          </material>
        </visual>
        <self_collide>0</self_collide>
        <enable_wind>0</enable_wind>
        <kinematic>0</kinematic>
      </link>
    </model>
    <light name='sun' type='directional'>
      <cast_shadows>1</cast_shadows>
      <pose frame=''>0 0 10 0 -0 0</pose>
      <diffuse>0.8 0.8 0.8 1</diffuse>
      <specular>0.2 0.2 0.2 1</specular>
      <attenuation>
        <range>1000</range>
        <constant>0.9</constant>
        <linear>0.01</linear>
        <quadratic>0.001</quadratic>
      </attenuation>
      <direction>-0.5 0.1 -0.9</direction>
    </light>
    <gravity>0 0 -9.8</gravity>
    <magnetic_field>6e-06 2.3e-05 -4.2e-05</magnetic_field>
    <atmosphere type='adiabatic'/>
    <physics name='default_physics' default='0' type='ode'>
      <max_step_size>0.001</max_step_size>
      <real_time_factor>1</real_time_factor>
      <real_time_update_rate>1000</real_time_update_rate>
    </physics>
    <scene>
      <ambient>0.4 0.4 0.4 1</ambient>
      <background>0.7 0.7 0.7 1</background>
      <shadows>1</shadows>
    </scene>
    <audio>
      <device>default</device>
    </audio>
    <wind/>
    <spherical_coordinates>
      <surface_model>EARTH_WGS84</surface_model>
      <latitude_deg>0</latitude_deg>
      <longitude_deg>0</longitude_deg>
      <elevation>0</elevation>
      <heading_deg>0</heading_deg>
    </spherical_coordinates>
    <model name='elderbot'>
      <link name='base_link'>
        <pose frame=''>0 0 0 0 -0 0</pose>
        <inertial>
          <pose frame=''>-0.002056 0 0.006 0 -0 0</pose>
          <mass>2.25</mass>
          <inertia>
            <ixx>0.0170744</ixx>
            <ixy>0</ixy>
            <ixz>0.000596625</ixz>
            <iyy>0.0185229</iyy>
            <iyz>0</iyz>
            <izz>0.0113493</izz>
          </inertia>
        </inertial>
        <collision name='base_link_fixed_joint_lump__chassis_collision'>
          <pose frame=''>0 0 0 0 -0 0</pose>
          <geometry>
            <box>
              <size>0.185 0.166 0.24</size>
            </box>
          </geometry>
          <max_contacts>10</max_contacts>
          <surface>
            <contact>
              <ode/>
            </contact>
            <bounce/>
            <friction>
              <torsional>
                <ode/>
              </torsional>
              <ode/>
            </friction>
          </surface>
        </collision>
        <collision name='base_link_fixed_joint_lump__laser_frame_collision_1'>
          <pose frame=''>-0.04625 0 0.135 0 -0 0</pose>
          <geometry>
            <cylinder>
              <length>0.03</length>
              <radius>0.03</radius>
            </cylinder>
          </geometry>
          <surface>
            <contact>
              <ode/>
            </contact>
            <friction>
              <ode/>
              <torsional>
                <ode/>
              </torsional>
            </friction>
            <bounce/>
          </surface>
          <max_contacts>10</max_contacts>
        </collision>
        <visual name='base_link_fixed_joint_lump__chassis_visual'>
          <pose frame=''>0 0 0 0 -0 0</pose>
          <geometry>
            <box>
              <size>0.185 0.166 0.24</size>
            </box>
          </geometry>
        </visual>
        <visual name='base_link_fixed_joint_lump__laser_frame_visual_1'>
          <pose frame=''>-0.04625 0 0.135 0 -0 0</pose>
          <geometry>
            <cylinder>
              <length>0.03</length>
              <radius>0.03</radius>
            </cylinder>
          </geometry>
          <material>
            <script>
              <name>Gazebo/Black</name>
              <uri>file://media/materials/scripts/gazebo.material</uri>
            </script>
          </material>
        </visual>
        <velocity_decay/>
        <gravity>1</gravity>
        <velocity_decay/>
        <sensor name='lidar' type='ray'>
          <visualize>1</visualize>
          <update_rate>10</update_rate>
          <ray>
            <scan>
              <horizontal>
                <samples>360</samples>
                <min_angle>-3.14</min_angle>
                <max_angle>3.14</max_angle>
                <resolution>1</resolution>
              </horizontal>
              <vertical>
                <samples>1</samples>
                <min_angle>0</min_angle>
                <max_angle>0</max_angle>
              </vertical>
            </scan>
            <range>
              <min>0.3</min>
              <max>12</max>
              <resolution>0.01</resolution>
            </range>
          </ray>
          <plugin name='gazebo_ros_ray_sensor' filename='libgazebo_ros_ray_sensor.so'>
            <ros>
              <argument>~/out:=scan</argument>
              <namespace>/</namespace>
            </ros>
            <output_type>sensor_msgs/LaserScan</output_type>
            <frameName>lidar_frame</frameName>
          </plugin>
          <pose frame=''>-0.04625 0 0.135 0 -0 0</pose>
        </sensor>
        <self_collide>0</self_collide>
        <enable_wind>0</enable_wind>
        <kinematic>0</kinematic>
      </link>
      <link name='left_front_wheel'>
        <pose frame=''>0.0925 0.0955 -0.12 -1.5708 0 0</pose>
        <inertial>
          <pose frame=''>0 0 0 0 -0 0</pose>
          <mass>0.035</mass>
          <inertia>
            <ixx>1.07829e-05</ixx>
            <ixy>0</ixy>
            <ixz>0</ixz>
            <iyy>1.792e-05</iyy>
            <iyz>0</iyz>
            <izz>1.07829e-05</izz>
          </inertia>
        </inertial>
        <collision name='left_front_wheel_collision'>
          <pose frame=''>0 0 0 0 -0 0</pose>
          <geometry>
            <cylinder>
              <length>0.025</length>
              <radius>0.032</radius>
            </cylinder>
          </geometry>
          <surface>
            <contact>
              <ode/>
            </contact>
            <friction>
              <ode/>
              <torsional>
                <ode/>
              </torsional>
            </friction>
            <bounce/>
          </surface>
          <max_contacts>10</max_contacts>
        </collision>
        <visual name='left_front_wheel_visual'>
          <pose frame=''>0 0 0 0 -0 0</pose>
          <geometry>
            <cylinder>
              <length>0.025</length>
              <radius>0.032</radius>
            </cylinder>
          </geometry>
          <material>
            <script>
              <name>Gazebo/Blue</name>
              <uri>file://media/materials/scripts/gazebo.material</uri>
            </script>
          </material>
        </visual>
        <gravity>1</gravity>
        <velocity_decay/>
        <self_collide>0</self_collide>
        <enable_wind>0</enable_wind>
        <kinematic>0</kinematic>
      </link>
      <joint name='left_front_wheel_joint' type='revolute'>
        <child>left_front_wheel</child>
        <parent>base_link</parent>
        <axis>
          <xyz>0 1 0</xyz>
          <limit>
            <lower>-1e+16</lower>
            <upper>1e+16</upper>
          </limit>
          <dynamics>
            <spring_reference>0</spring_reference>
            <spring_stiffness>0</spring_stiffness>
          </dynamics>
          <use_parent_model_frame>1</use_parent_model_frame>
        </axis>
      </joint>
      <link name='left_rear_wheel'>
        <pose frame=''>-0.0925 0.0955 -0.12 -1.5708 0 0</pose>
        <inertial>
          <pose frame=''>0 0 0 0 -0 0</pose>
          <mass>0.035</mass>
          <inertia>
            <ixx>1.07829e-05</ixx>
            <ixy>0</ixy>
            <ixz>0</ixz>
            <iyy>1.792e-05</iyy>
            <iyz>0</iyz>
            <izz>1.07829e-05</izz>
          </inertia>
        </inertial>
        <collision name='left_rear_wheel_collision'>
          <pose frame=''>0 0 0 0 -0 0</pose>
          <geometry>
            <cylinder>
              <length>0.025</length>
              <radius>0.032</radius>
            </cylinder>
          </geometry>
          <surface>
            <contact>
              <ode/>
            </contact>
            <friction>
              <ode/>
              <torsional>
                <ode/>
              </torsional>
            </friction>
            <bounce/>
          </surface>
          <max_contacts>10</max_contacts>
        </collision>
        <visual name='left_rear_wheel_visual'>
          <pose frame=''>0 0 0 0 -0 0</pose>
          <geometry>
            <cylinder>
              <length>0.025</length>
              <radius>0.032</radius>
            </cylinder>
          </geometry>
          <material>
            <script>
              <name>Gazebo/Blue</name>
              <uri>file://media/materials/scripts/gazebo.material</uri>
            </script>
          </material>
        </visual>
        <gravity>1</gravity>
        <velocity_decay/>
        <self_collide>0</self_collide>
        <enable_wind>0</enable_wind>
        <kinematic>0</kinematic>
      </link>
      <joint name='left_rear_wheel_joint' type='revolute'>
        <child>left_rear_wheel</child>
        <parent>base_link</parent>
        <axis>
          <xyz>0 1 0</xyz>
          <limit>
            <lower>-1e+16</lower>
            <upper>1e+16</upper>
          </limit>
          <dynamics>
            <spring_reference>0</spring_reference>
            <spring_stiffness>0</spring_stiffness>
          </dynamics>
          <use_parent_model_frame>1</use_parent_model_frame>
        </axis>
      </joint>
      <link name='right_front_wheel'>
        <pose frame=''>0.0925 -0.0955 -0.12 1.5708 -0 0</pose>
        <inertial>
          <pose frame=''>0 0 0 0 -0 0</pose>
          <mass>0.035</mass>
          <inertia>
            <ixx>1.07829e-05</ixx>
            <ixy>0</ixy>
            <ixz>0</ixz>
            <iyy>1.792e-05</iyy>
            <iyz>0</iyz>
            <izz>1.07829e-05</izz>
          </inertia>
        </inertial>
        <collision name='right_front_wheel_collision'>
          <pose frame=''>0 0 0 0 -0 0</pose>
          <geometry>
            <cylinder>
              <length>0.025</length>
              <radius>0.032</radius>
            </cylinder>
          </geometry>
          <surface>
            <contact>
              <ode/>
            </contact>
            <friction>
              <ode/>
              <torsional>
                <ode/>
              </torsional>
            </friction>
            <bounce/>
          </surface>
          <max_contacts>10</max_contacts>
        </collision>
        <visual name='right_front_wheel_visual'>
          <pose frame=''>0 0 0 0 -0 0</pose>
          <geometry>
            <cylinder>
              <length>0.025</length>
              <radius>0.032</radius>
            </cylinder>
          </geometry>
          <material>
            <script>
              <name>Gazebo/Blue</name>
              <uri>file://media/materials/scripts/gazebo.material</uri>
            </script>
          </material>
        </visual>
        <gravity>1</gravity>
        <velocity_decay/>
        <self_collide>0</self_collide>
        <enable_wind>0</enable_wind>
        <kinematic>0</kinematic>
      </link>
      <joint name='right_front_wheel_joint' type='revolute'>
        <child>right_front_wheel</child>
        <parent>base_link</parent>
        <axis>
          <xyz>0 1 -0</xyz>
          <limit>
            <lower>-1e+16</lower>
            <upper>1e+16</upper>
          </limit>
          <dynamics>
            <spring_reference>0</spring_reference>
            <spring_stiffness>0</spring_stiffness>
          </dynamics>
          <use_parent_model_frame>1</use_parent_model_frame>
        </axis>
      </joint>
      <link name='right_rear_wheel'>
        <pose frame=''>-0.0925 -0.0955 -0.12 1.5708 -0 0</pose>
        <inertial>
          <pose frame=''>0 0 0 0 -0 0</pose>
          <mass>0.035</mass>
          <inertia>
            <ixx>1.07829e-05</ixx>
            <ixy>0</ixy>
            <ixz>0</ixz>
            <iyy>1.792e-05</iyy>
            <iyz>0</iyz>
            <izz>1.07829e-05</izz>
          </inertia>
        </inertial>
        <collision name='right_rear_wheel_collision'>
          <pose frame=''>0 0 0 0 -0 0</pose>
          <geometry>
            <cylinder>
              <length>0.025</length>
              <radius>0.032</radius>
            </cylinder>
          </geometry>
          <surface>
            <contact>
              <ode/>
            </contact>
            <friction>
              <ode/>
              <torsional>
                <ode/>
              </torsional>
            </friction>
            <bounce/>
          </surface>
          <max_contacts>10</max_contacts>
        </collision>
        <visual name='right_rear_wheel_visual'>
          <pose frame=''>0 0 0 0 -0 0</pose>
          <geometry>
            <cylinder>
              <length>0.025</length>
              <radius>0.032</radius>
            </cylinder>
          </geometry>
          <material>
            <script>
              <name>Gazebo/Blue</name>
              <uri>file://media/materials/scripts/gazebo.material</uri>
            </script>
          </material>
        </visual>
        <gravity>1</gravity>
        <velocity_decay/>
        <self_collide>0</self_collide>
        <enable_wind>0</enable_wind>
        <kinematic>0</kinematic>
      </link>
      <joint name='right_rear_wheel_joint' type='revolute'>
        <child>right_rear_wheel</child>
        <parent>base_link</parent>
        <axis>
          <xyz>0 1 -0</xyz>
          <limit>
            <lower>-1e+16</lower>
            <upper>1e+16</upper>
          </limit>
          <dynamics>
            <spring_reference>0</spring_reference>
            <spring_stiffness>0</spring_stiffness>
          </dynamics>
          <use_parent_model_frame>1</use_parent_model_frame>
        </axis>
      </joint>
      <static>0</static>
      <plugin name='diff_drive' filename='libgazebo_ros_diff_drive.so'>
        <left_joint>left_rear_wheel_joint</left_joint>
        <right_joint>right_rear_wheel_joint</right_joint>
        <wheel_separation>0.191</wheel_separation>
        <wheel_diameter>0.064</wheel_diameter>
        <command_topic>cmd_vel</command_topic>
        <odometry_topic>odom</odometry_topic>
        <odometry_frame>odom</odometry_frame>
        <robot_base_frame>base_link</robot_base_frame>
        <publishWheelTF>1</publishWheelTF>
        <publishOdom>1</publishOdom>
        <publishWheelJointState>1</publishWheelJointState>
        <legacyMode>0</legacyMode>
        <ros>
          <namespace>/</namespace>
        </ros>
      </plugin>
      <plugin name='joint_state_publisher' filename='libgazebo_ros_joint_state_publisher.so'>
        <update_rate>50</update_rate>
        <joint_name>left_front_wheel_joint</joint_name>
        <joint_name>right_front_wheel_joint</joint_name>
        <joint_name>left_rear_wheel_joint</joint_name>
        <joint_name>right_rear_wheel_joint</joint_name>
        <ros>
          <namespace>/</namespace>
        </ros>
      </plugin>
      <pose frame=''>0 0 0.1 0 -0 0</pose>
    </model>
    <model name='ros_symbol'>
      <static>1</static>
      <link name='symbol'>
        <collision name='one_one'>
          <pose frame=''>-1.1 -1.1 0.25 0 -0 0</pose>
          <geometry>
            <cylinder>
              <radius>0.15</radius>
              <length>0.5</length>
            </cylinder>
          </geometry>
          <max_contacts>10</max_contacts>
          <surface>
            <bounce/>
            <friction>
              <ode/>
              <torsional>
                <ode/>
              </torsional>
            </friction>
            <contact>
              <ode/>
            </contact>
          </surface>
        </collision>
        <visual name='one_one'>
          <pose frame=''>-1.1 -1.1 0.25 0 -0 0</pose>
          <geometry>
            <cylinder>
              <radius>0.15</radius>
              <length>0.5</length>
            </cylinder>
          </geometry>
          <material>
            <script>
              <uri>file://media/materials/scripts/gazebo.material</uri>
              <name>Gazebo/White</name>
            </script>
          </material>
        </visual>
        <collision name='one_two'>
          <pose frame=''>-1.1 0 0.25 0 -0 0</pose>
          <geometry>
            <cylinder>
              <radius>0.15</radius>
              <length>0.5</length>
            </cylinder>
          </geometry>
          <max_contacts>10</max_contacts>
          <surface>
            <bounce/>
            <friction>
              <ode/>
              <torsional>
                <ode/>
              </torsional>
            </friction>
            <contact>
              <ode/>
            </contact>
          </surface>
        </collision>
        <visual name='one_two'>
          <pose frame=''>-1.1 0 0.25 0 -0 0</pose>
          <geometry>
            <cylinder>
              <radius>0.15</radius>
              <length>0.5</length>
            </cylinder>
          </geometry>
          <material>
            <script>
              <uri>file://media/materials/scripts/gazebo.material</uri>
              <name>Gazebo/White</name>
            </script>
          </material>
        </visual>
        <collision name='one_three'>
          <pose frame=''>-1.1 1.1 0.25 0 -0 0</pose>
          <geometry>
            <cylinder>
              <radius>0.15</radius>
              <length>0.5</length>
            </cylinder>
          </geometry>
          <max_contacts>10</max_contacts>
          <surface>
            <bounce/>
            <friction>
              <ode/>
              <torsional>
                <ode/>
              </torsional>
            </friction>
            <contact>
              <ode/>
            </contact>
          </surface>
        </collision>
        <visual name='one_three'>
          <pose frame=''>-1.1 1.1 0.25 0 -0 0</pose>
          <geometry>
            <cylinder>
              <radius>0.15</radius>
              <length>0.5</length>
            </cylinder>
          </geometry>
          <material>
            <script>
              <uri>file://media/materials/scripts/gazebo.material</uri>
              <name>Gazebo/White</name>
            </script>
          </material>
        </visual>
        <collision name='two_one'>
          <pose frame=''>0 -1.1 0.25 0 -0 0</pose>
          <geometry>
            <cylinder>
              <radius>0.15</radius>
              <length>0.5</length>
            </cylinder>
          </geometry>
          <max_contacts>10</max_contacts>
          <surface>
            <bounce/>
            <friction>
              <ode/>
              <torsional>
                <ode/>
              </torsional>
            </friction>
            <contact>
              <ode/>
            </contact>
          </surface>
        </collision>
        <visual name='two_one'>
          <pose frame=''>0 -1.1 0.25 0 -0 0</pose>
          <geometry>
            <cylinder>
              <radius>0.15</radius>
              <length>0.5</length>
            </cylinder>
          </geometry>
          <material>
            <script>
              <uri>file://media/materials/scripts/gazebo.material</uri>
              <name>Gazebo/White</name>
            </script>
          </material>
        </visual>
        <collision name='two_two'>
          <pose frame=''>0 0 0.25 0 -0 0</pose>
          <geometry>
            <cylinder>
              <radius>0.15</radius>
              <length>0.5</length>
            </cylinder>
          </geometry>
          <max_contacts>10</max_contacts>
          <surface>
            <bounce/>
            <friction>
              <ode/>
              <torsional>
                <ode/>
              </torsional>
            </friction>
            <contact>
              <ode/>
            </contact>
          </surface>
        </collision>
        <visual name='two_two'>
          <pose frame=''>0 0 0.25 0 -0 0</pose>
          <geometry>
            <cylinder>
              <radius>0.15</radius>
              <length>0.5</length>
            </cylinder>
          </geometry>
          <material>
            <script>
              <uri>file://media/materials/scripts/gazebo.material</uri>
              <name>Gazebo/White</name>
            </script>
          </material>
        </visual>
        <collision name='two_three'>
          <pose frame=''>0 1.1 0.25 0 -0 0</pose>
          <geometry>
            <cylinder>
              <radius>0.15</radius>
              <length>0.5</length>
            </cylinder>
          </geometry>
          <max_contacts>10</max_contacts>
          <surface>
            <bounce/>
            <friction>
              <ode/>
              <torsional>
                <ode/>
              </torsional>
            </friction>
            <contact>
              <ode/>
            </contact>
          </surface>
        </collision>
        <visual name='two_three'>
          <pose frame=''>0 1.1 0.25 0 -0 0</pose>
          <geometry>
            <cylinder>
              <radius>0.15</radius>
              <length>0.5</length>
            </cylinder>
          </geometry>
          <material>
            <script>
              <uri>file://media/materials/scripts/gazebo.material</uri>
              <name>Gazebo/White</name>
            </script>
          </material>
        </visual>
        <collision name='three_one'>
          <pose frame=''>1.1 -1.1 0.25 0 -0 0</pose>
          <geometry>
            <cylinder>
              <radius>0.15</radius>
              <length>0.5</length>
            </cylinder>
          </geometry>
          <max_contacts>10</max_contacts>
          <surface>
            <bounce/>
            <friction>
              <ode/>
              <torsional>
                <ode/>
              </torsional>
            </friction>
            <contact>
              <ode/>
            </contact>
          </surface>
        </collision>
        <visual name='three_one'>
          <pose frame=''>1.1 -1.1 0.25 0 -0 0</pose>
          <geometry>
            <cylinder>
              <radius>0.15</radius>
              <length>0.5</length>
            </cylinder>
          </geometry>
          <material>
            <script>
              <uri>file://media/materials/scripts/gazebo.material</uri>
              <name>Gazebo/White</name>
            </script>
          </material>
        </visual>
        <collision name='three_two'>
          <pose frame=''>1.1 0 0.25 0 -0 0</pose>
          <geometry>
            <cylinder>
              <radius>0.15</radius>
              <length>0.5</length>
            </cylinder>
          </geometry>
          <max_contacts>10</max_contacts>
          <surface>
            <bounce/>
            <friction>
              <ode/>
              <torsional>
                <ode/>
              </torsional>
            </friction>
            <contact>
              <ode/>
            </contact>
          </surface>
        </collision>
        <visual name='three_two'>
          <pose frame=''>1.1 0 0.25 0 -0 0</pose>
          <geometry>
            <cylinder>
              <radius>0.15</radius>
              <length>0.5</length>
            </cylinder>
          </geometry>
          <material>
            <script>
              <uri>file://media/materials/scripts/gazebo.material</uri>
              <name>Gazebo/White</name>
            </script>
          </material>
        </visual>
        <collision name='three_three'>
          <pose frame=''>1.1 1.1 0.25 0 -0 0</pose>
          <geometry>
            <cylinder>
              <radius>0.15</radius>
              <length>0.5</length>
            </cylinder>
          </geometry>
          <max_contacts>10</max_contacts>
          <surface>
            <bounce/>
            <friction>
              <ode/>
              <torsional>
                <ode/>
              </torsional>
            </friction>
            <contact>
              <ode/>
            </contact>
          </surface>
        </collision>
        <visual name='three_three'>
          <pose frame=''>1.1 1.1 0.25 0 -0 0</pose>
          <geometry>
            <cylinder>
              <radius>0.15</radius>
              <length>0.5</length>
            </cylinder>
          </geometry>
          <material>
            <script>
              <uri>file://media/materials/scripts/gazebo.material</uri>
              <name>Gazebo/White</name>
            </script>
          </material>
        </visual>
        <collision name='head'>
          <pose frame=''>3.5 0 -0.5 0 -0 0</pose>
          <geometry>
            <mesh>
              <uri>model://turtlebot3_world/meshes/hexagon.dae</uri>
              <scale>0.8 0.8 0.8</scale>
            </mesh>
          </geometry>
          <max_contacts>10</max_contacts>
          <surface>
            <bounce/>
            <friction>
              <ode/>
              <torsional>
                <ode/>
              </torsional>
            </friction>
            <contact>
              <ode/>
            </contact>
          </surface>
        </collision>
        <visual name='head'>
          <pose frame=''>3.5 0 -0.5 0 -0 0</pose>
          <geometry>
            <mesh>
              <uri>model://turtlebot3_world/meshes/hexagon.dae</uri>
              <scale>0.8 0.8 0.8</scale>
            </mesh>
          </geometry>
          <material>
            <script>
              <uri>file://media/materials/scripts/gazebo.material</uri>
              <name>Gazebo/Green</name>
            </script>
          </material>
        </visual>
        <collision name='left_hand'>
          <pose frame=''>1.8 2.7 0 0 -0 0</pose>
          <geometry>
            <mesh>
              <uri>model://turtlebot3_world/meshes/hexagon.dae</uri>
              <scale>0.55 0.55 0.55</scale>
            </mesh>
          </geometry>
          <max_contacts>10</max_contacts>
          <surface>
            <bounce/>
            <friction>
              <ode/>
              <torsional>
                <ode/>
              </torsional>
            </friction>
            <contact>
              <ode/>
            </contact>
          </surface>
        </collision>
        <visual name='left_hand'>
          <pose frame=''>1.8 2.7 0 0 -0 0</pose>
          <geometry>
            <mesh>
              <uri>model://turtlebot3_world/meshes/hexagon.dae</uri>
              <scale>0.55 0.55 0.55</scale>
            </mesh>
          </geometry>
          <material>
            <script>
              <uri>file://media/materials/scripts/gazebo.material</uri>
              <name>Gazebo/Green</name>
            </script>
          </material>
        </visual>
        <collision name='right_hand'>
          <pose frame=''>1.8 -2.7 0 0 -0 0</pose>
          <geometry>
            <mesh>
              <uri>model://turtlebot3_world/meshes/hexagon.dae</uri>
              <scale>0.55 0.55 0.55</scale>
            </mesh>
          </geometry>
          <max_contacts>10</max_contacts>
          <surface>
            <bounce/>
            <friction>
              <ode/>
              <torsional>
                <ode/>
              </torsional>
            </friction>
            <contact>
              <ode/>
            </contact>
          </surface>
        </collision>
        <visual name='right_hand'>
          <pose frame=''>1.8 -2.7 0 0 -0 0</pose>
          <geometry>
            <mesh>
              <uri>model://turtlebot3_world/meshes/hexagon.dae</uri>
              <scale>0.55 0.55 0.55</scale>
            </mesh>
          </geometry>
          <material>
            <script>
              <uri>file://media/materials/scripts/gazebo.material</uri>
              <name>Gazebo/Green</name>
            </script>
          </material>
        </visual>
        <collision name='left_foot'>
          <pose frame=''>-1.8 2.7 0 0 -0 0</pose>
          <geometry>
            <mesh>
              <uri>model://turtlebot3_world/meshes/hexagon.dae</uri>
              <scale>0.55 0.55 0.55</scale>
            </mesh>
          </geometry>
          <max_contacts>10</max_contacts>
          <surface>
            <bounce/>
            <friction>
              <ode/>
              <torsional>
                <ode/>
              </torsional>
            </friction>
            <contact>
              <ode/>
            </contact>
          </surface>
        </collision>
        <visual name='left_foot'>
          <pose frame=''>-1.8 2.7 0 0 -0 0</pose>
          <geometry>
            <mesh>
              <uri>model://turtlebot3_world/meshes/hexagon.dae</uri>
              <scale>0.55 0.55 0.55</scale>
            </mesh>
          </geometry>
          <material>
            <script>
              <uri>file://media/materials/scripts/gazebo.material</uri>
              <name>Gazebo/Green</name>
            </script>
          </material>
        </visual>
        <collision name='right_foot'>
          <pose frame=''>-1.8 -2.7 0 0 -0 0</pose>
          <geometry>
            <mesh>
              <uri>model://turtlebot3_world/meshes/hexagon.dae</uri>
              <scale>0.55 0.55 0.55</scale>
            </mesh>
          </geometry>
          <max_contacts>10</max_contacts>
          <surface>
            <bounce/>
            <friction>
              <ode/>
              <torsional>
                <ode/>
              </torsional>
            </friction>
            <contact>
              <ode/>
            </contact>
          </surface>
        </collision>
        <visual name='right_foot'>
          <pose frame=''>-1.8 -2.7 0 0 -0 0</pose>
          <geometry>
            <mesh>
              <uri>model://turtlebot3_world/meshes/hexagon.dae</uri>
              <scale>0.55 0.55 0.55</scale>
            </mesh>
          </geometry>
          <material>
            <script>
              <uri>file://media/materials/scripts/gazebo.material</uri>
              <name>Gazebo/Green</name>
            </script>
          </material>
        </visual>
        <collision name='body'>
          <pose frame=''>0 0 -0.3 0 0 -1.5708</pose>
          <geometry>
            <mesh>
              <uri>model://turtlebot3_world/meshes/wall.dae</uri>
              <scale>0.25 0.25 0.25</scale>
            </mesh>
          </geometry>
          <max_contacts>10</max_contacts>
          <surface>
            <bounce/>
            <friction>
              <ode/>
              <torsional>
                <ode/>
              </torsional>
            </friction>
            <contact>
              <ode/>
            </contact>
          </surface>
        </collision>
        <visual name='body'>
          <pose frame=''>0 0 -0.3 0 0 -1.5708</pose>
          <geometry>
            <mesh>
              <uri>model://turtlebot3_world/meshes/wall.dae</uri>
              <scale>0.25 0.25 0.25</scale>
            </mesh>
          </geometry>
          <material>
            <script>
              <uri>file://media/materials/scripts/gazebo.material</uri>
              <name>Gazebo/FlatBlack</name>
            </script>
          </material>
        </visual>
        <self_collide>0</self_collide>
        <enable_wind>0</enable_wind>
        <kinematic>0</kinematic>
      </link>
      <pose frame=''>-0.619862 -0.667002 0 0 -0 0</pose>
    </model>
    <state world_name='simple_world'>
      <sim_time>442 434000000</sim_time>
      <real_time>473 780797514</real_time>
      <wall_time>1757257861 450179678</wall_time>
      <iterations>442434</iterations>
      <model name='elderbot'>
        <pose frame=''>0.006678 0.004436 0.151999 -0 -1e-06 0.021267</pose>
        <scale>1 1 1</scale>
        <link name='base_link'>
          <pose frame=''>0.006678 0.004436 0.151999 -0 -1e-06 0.021267</pose>
          <velocity>-1.8e-05 1e-06 -3e-06 0 -1e-06 -2e-06</velocity>
          <acceleration>4e-06 -0 7e-06 1e-06 3e-06 -3e-06</acceleration>
          <wrench>9e-06 -1e-06 1.7e-05 0 -0 0</wrench>
        </link>
        <link name='left_front_wheel'>
          <pose frame=''>0.097127 0.101881 0.032001 -1.57086 0.410101 0.021251</pose>
          <velocity>-1.8e-05 3e-06 -3e-06 0.000268 -0.000465 -4.4e-05</velocity>
          <acceleration>4e-06 -8e-06 7e-06 -0.000723 -0.000167 0.000189</acceleration>
          <wrench>0 -0 0 0 -0 0</wrench>
        </link>
        <link name='left_rear_wheel'>
          <pose frame=''>-0.087832 0.097946 0.032001 -1.57085 -0.121183 0.021271</pose>
          <velocity>-1.8e-05 4e-06 -3e-06 0.000289 -0.000551 1.2e-05</velocity>
          <acceleration>4e-06 -7e-06 8e-06 -0.000795 0.000244 -6.5e-05</acceleration>
          <wrench>0 -0 0 0 -0 0</wrench>
        </link>
        <link name='right_front_wheel'>
          <pose frame=''>0.101188 -0.089074 0.032 1.57085 0.749096 0.021294</pose>
          <velocity>-1.8e-05 -2e-06 -2e-06 -0.000221 -0.000488 5.6e-05</velocity>
          <acceleration>3e-06 8e-06 7e-06 0.000589 -0.000218 -0.00027</acceleration>
          <wrench>0 0 0 0 -0 0</wrench>
        </link>
        <link name='right_rear_wheel'>
          <pose frame=''>-0.08377 -0.093009 0.032 1.57083 0.147428 0.021271</pose>
          <velocity>-1.8e-05 -1e-06 -3e-06 -0.000259 -0.000542 1.5e-05</velocity>
          <acceleration>3e-06 8e-06 8e-06 0.000773 9.2e-05 -7.7e-05</acceleration>
          <wrench>0 0 0 0 -0 0</wrench>
        </link>
      </model>
      <model name='ground_plane'>
        <pose frame=''>0 0 0 0 -0 0</pose>
        <scale>1 1 1</scale>
        <link name='link'>
          <pose frame=''>0 0 0 0 -0 0</pose>
          <velocity>0 0 0 0 -0 0</velocity>
          <acceleration>0 0 0 0 -0 0</acceleration>
          <wrench>0 0 0 0 -0 0</wrench>
        </link>
      </model>
      <model name='ros_symbol'>
        <pose frame=''>-0.619862 -0.667002 0 0 -0 0</pose>
        <scale>1 1 1</scale>
        <link name='symbol'>
          <pose frame=''>-0.619862 -0.667002 0 0 -0 0</pose>
          <velocity>0 0 0 0 -0 0</velocity>
          <acceleration>0 0 0 0 -0 0</acceleration>
          <wrench>0 0 0 0 -0 0</wrench>
        </link>
      </model>
      <light name='sun'>
        <pose frame=''>0 0 10 0 -0 0</pose>
      </light>
    </state>
    <gui fullscreen='0'>
      <camera name='user_camera'>
        <pose frame=''>-2.96934 6.13637 10.0976 0 1.01164 -1.23499</pose>
        <view_controller>orbit</view_controller>
        <projection_type>perspective</projection_type>
      </camera>
    </gui>
  </world>
</sdf>
